/Users/haotianyang/test/pytorch-from-centralized-to-federated/.venv/lib/python3.9/site-packages/urllib3/__init__.py:35: NotOpenSSLWarning: urllib3 v2 only supports OpenSSL 1.1.1+, currently the 'ssl' module is compiled with 'LibreSSL 2.8.3'. See: https://github.com/urllib3/urllib3/issues/3020
  warnings.warn(
[92mINFO [0m:      
[92mINFO [0m:      Received: evaluate message 6de86f7b-72ec-45bf-8b41-546d77e725e2
Client Evaluation: 
Test Accuracy: 0.088, Test Loss: 230.38200306892395
[92mINFO [0m:      Sent reply
[92mINFO [0m:      
[92mINFO [0m:      Received: train message 90add34b-868f-42a3-914f-7d9f8f695bce
Train Epoch: 0 [0/600 (0%)]	Loss: 2.318165
Test Accuracy: 0.1002, Test Loss: 230.25322556495667
[92mINFO [0m:      Sent reply
[92mINFO [0m:      
[92mINFO [0m:      Received: evaluate message 751d27ea-e6d3-4d02-8f92-209c25ddf757
Client Evaluation: 
Test Accuracy: 0.0949, Test Loss: 230.25880360603333
[92mINFO [0m:      Sent reply
[92mINFO [0m:      
[92mINFO [0m:      Received: train message a0699648-807d-4a3d-8162-cdaf7ba3625e
Train Epoch: 0 [0/600 (0%)]	Loss: 2.304844
Test Accuracy: 0.1044, Test Loss: 230.13138699531555
[92mINFO [0m:      Sent reply
E0705 13:59:50.698701000 14512320512 tcp_posix.cc:598]                 recvmsg encountered uncommon error: Message too long
[92mINFO [0m:      
[92mINFO [0m:      Received: evaluate message 16a783a4-b538-4e3c-a34a-d5fa5be347f2
Client Evaluation: 
Test Accuracy: 0.1014, Test Loss: 230.1357123851776
[92mINFO [0m:      Sent reply
[92mINFO [0m:      
[92mINFO [0m:      Received: train message 141cb7be-0ec2-457f-9c74-51c16682e034
Train Epoch: 0 [0/600 (0%)]	Loss: 2.303398
Test Accuracy: 0.1101, Test Loss: 229.99738121032715
[92mINFO [0m:      Sent reply
E0705 14:01:44.227921000 14512320512 tcp_posix.cc:598]                 recvmsg encountered uncommon error: Message too long
[92mINFO [0m:      
[92mINFO [0m:      Received: evaluate message 7c9e1d08-1ffd-4e11-b820-0e0c2eb458d9
Client Evaluation: 
Test Accuracy: 0.1074, Test Loss: 230.011225938797
[92mINFO [0m:      Sent reply
[92mINFO [0m:      
[92mINFO [0m:      Received: train message 6e4e2802-c5bb-4d97-817f-a62317a2c44e
Train Epoch: 0 [0/600 (0%)]	Loss: 2.301101
Test Accuracy: 0.1168, Test Loss: 229.87251257896423
[92mINFO [0m:      Sent reply
E0705 14:03:09.931056000 14512320512 tcp_posix.cc:598]                 recvmsg encountered uncommon error: Message too long
[92mINFO [0m:      
[92mINFO [0m:      Received: evaluate message 26bd28b6-a6e8-4f90-8f42-d37b925c7732
Client Evaluation: 
Test Accuracy: 0.1141, Test Loss: 229.8874170780182
[92mINFO [0m:      Sent reply
E0705 14:04:02.768192000 14512320512 tcp_posix.cc:598]                 recvmsg encountered uncommon error: Message too long
[92mINFO [0m:      
[92mINFO [0m:      Received: train message 822da53c-728f-44c4-b05a-e75d174dd76b
Train Epoch: 0 [0/600 (0%)]	Loss: 2.292187
Test Accuracy: 0.1175, Test Loss: 229.7576277256012
[92mINFO [0m:      Sent reply
[92mINFO [0m:      
[92mINFO [0m:      Received: evaluate message 33a83edc-3668-4063-ac42-a32ff93c45a0
Client Evaluation: 
Test Accuracy: 0.1186, Test Loss: 229.76430010795593
[92mINFO [0m:      Sent reply
E0705 14:12:05.843267000 14512320512 tcp_posix.cc:598]                 recvmsg encountered uncommon error: Message too long
[92mINFO [0m:      
[92mINFO [0m:      Received: train message 26f9f865-521f-46fa-8204-2407ed43c80a
Train Epoch: 0 [0/600 (0%)]	Loss: 2.300349
Test Accuracy: 0.1261, Test Loss: 229.63430261611938
[92mINFO [0m:      Sent reply
Traceback (most recent call last):
  File "/Users/haotianyang/test/pytorch-from-centralized-to-federated/client.py", line 102, in <module>
    main()
  File "/Users/haotianyang/test/pytorch-from-centralized-to-federated/client.py", line 98, in main
    fl.client.start_client(server_address="127.0.0.1:8080", client=client)
  File "/Users/haotianyang/test/pytorch-from-centralized-to-federated/.venv/lib/python3.9/site-packages/flwr/client/app.py", line 157, in start_client
    _start_client_internal(
  File "/Users/haotianyang/test/pytorch-from-centralized-to-federated/.venv/lib/python3.9/site-packages/flwr/client/app.py", line 333, in _start_client_internal
    message = receive()
  File "/Users/haotianyang/test/pytorch-from-centralized-to-federated/.venv/lib/python3.9/site-packages/flwr/client/grpc_client/connection.py", line 144, in receive
    proto = next(server_message_iterator)
  File "/Users/haotianyang/test/pytorch-from-centralized-to-federated/.venv/lib/python3.9/site-packages/grpc/_channel.py", line 543, in __next__
    return self._next()
  File "/Users/haotianyang/test/pytorch-from-centralized-to-federated/.venv/lib/python3.9/site-packages/grpc/_channel.py", line 969, in _next
    raise self
grpc._channel._MultiThreadedRendezvous: <_MultiThreadedRendezvous of RPC that terminated with:
	status = StatusCode.UNAVAILABLE
	details = "ping timeout"
	debug_error_string = "UNKNOWN:Error received from peer ipv4:127.0.0.1:8080 {created_time:"2024-07-05T14:18:48.375565-07:00", grpc_status:14, grpc_message:"ping timeout"}"
>
